Workbook

Sheet Bloc details

Sheet Suivi des Chambres
A1: Avancement global | E1: =IFERROR(SUM(E$5:E$132)/COUNT($D$5:$D$132),0) -> 1 | F1: =IFERROR(SUM(F$5:F$132)/COUNT($D$5:$D$132),0) -> 1 | G1: =IFERROR(SUM(G$5:G$132)/COUNT($D$5:$D$132),0) -> 1 | H1: =IFERROR(SUM(H$5:H$132)/COUNT($D$5:$D$132),0) -> 1 | I1: =IFERROR(SUM(I$5:I$132)/COUNT($D$5:$D$132),0) -> 1 | J1: =IFERROR(SUM(J$5:J$132)/COUNT($D$5:$D$132),0) -> 0 | K1: =IFERROR(SUM(K$5:K$132)/COUNT($D$5:$D$132),0) -> 0.02578125 | L1: =IFERROR(SUM(L$5:L$132)/COUNT($D$5:$D$132),0) -> 0.58671875 | ... BT1: =IFERROR(SUM(BT$5:BT$132)/COUNT($D$5:$D$132),0) -> 0
A2: IDENTIFICATION | E2: SDB | AN2: CHAMBRE
E3: Plomberie sol | H3: Cloisons | I3: Électricité cloisons | L3: Étanchéité | O3: Dressage | P3: Chape | Q3: Faux plafond SDB | X3: Peinture FP | Y3: Revêtement mural | AA3: Revêtement sol | AB3: Menuiserie alu | AD3: Menuiserie bois | AF3: Agencement | AG3: Sanitaires | AH3: Accessoires | AI3: Tests | AL3: Réception | AN3: Cloisons | AO3: Électricité cloisons | AR3: Chape | AS3: Faux plafond chambre | BA3: Menuiserie bois | BD3: Menuiserie alu | BE3: Peinture | BI3: Revêtement sol | BK3: Agencement fixe | BN3: Appareillage | BP3: Tests | BS3: LOGGIA
A4: Étage | B4: Bloc | C4: Type chambre | D4: N Chambre | E4: Passage EF/EC | F4: Passage évacuations | G4: Bon à etanché plomberie sol | H4: Cloisons SDB posées | I4: Passage électricité cloisons | J4: Bon à enduire électricité cloisons | K4: calfeutrement | L4: Étanchéité SDB | M4: Test mise en eau | N4: PV test mise en eau | O4: Dressage mur | P4: Chape / forme de pente | Q4: Structure faux plafond | R4: Réseaux électricité plafond | S4: Réseaux clim / ventilation | T4: Trappe de visite | U4: Bon à fermer faux plafond | V4: Fermeture faux plafond | W4: Finition faux plafond | X4: Peinture faux plafond | Y4: Pose revêtement toilette | Z4: Pose revêtement douche | AA4: Pose revêtement sol | AB4: Faux cadres alu | AC4: Pose châssis / cabine douche / cabine WC | AD4: Rail porte coulissante | AE4: Fermeture cloison porte coulissante | AF4: Pose vanity | AG4: Pose sanitaires / robinetterie | AH4: Pose accessoires SDB | AI4: Essais plomberie | AJ4: Essais électricité | AK4: Essais CVC | AL4: Finitions SDB | AM4: Réception interne SDB | AN4: Cloisons chambre | AO4: Passage électricité cloisons | AP4: Bon à enduire électricité cloisons | AQ4: Calfeutrement | AR4: Chape chambre | AS4: Structure faux plafond | AT4: Réseaux électricité plafond | AU4: Réseaux sprinklage / détection | AV4: Réseaux clim | AW4: Bon à fermer faux plafond | AX4: Pose faux plafond | AY4: Finition faux plafond | AZ4: Peinture faux plafond | BA4: Faux cadres porte entrée | BB4: Pose porte entrée | BC4: Pose porte SDB | BD4: Pose fenêtres | BE4: Enduit 1ère couche | BF4: Enduit 2ème couche | BG4: Peinture 1ère couche | BH4: Peinture 2ème couche | BI4: Pose sol fini | BJ4: Pose plinthes | BK4: Armoire / bar | BL4: Tête de lit | BM4: Meuble TV / bureau | BN4: Appareillage électrique | BO4: Luminaires / liseuses | BP4: Essais électricité | BQ4: Essais climatisation | BR4: Essais serrure carte | BS4: Pose faux cadres | BT4: Pose menuiserie
A5: R+2 | B5: Bloc A | C5: Standard | D5: 201 | E5: 1 | F5: 1 | G5: 1 | H5: 1 | I5: 1 | J5: A demander | L5: 1 | N5: A demander | P5: 0 | Q5: 1 | R5: À demander | S5: A demander | T5: 0 | U5: A demander | V5: 0 | W5: 0 | X5: 0 | Y5: 0 | Z5: 0 | AA5: 0 | AB5: 0 | AC5: 0 | AD5: 0 | AE5: 0 | AF5: 0 | AG5: 0 | AH5: 0 | AI5: A demander | AJ5: A demander | AK5: A demander | AL5: 0 | AM5: 0 | AO5: A demander | AP5: A demander | AR5: 1 | AU5: 1 | AV5: 1 | BI5: 0 | BJ5: 0 | BK5: 0 | BL5: 0 | BM5: 0 | BN5: 0 | BO5: 0
B6: Bloc A | C6: Standard | D6: 202 | E6: 1 | F6: 1 | G6: 1 | H6: 1 | I6: 1 | J6: A demander | L6: 1 | N6: A demander | P6: 0 | Q6: 1 | R6: À demander | S6: A demander | T6: 0 | U6: A demander | V6: 0 | W6: 0 | X6: 0 | Y6: 0 | Z6: 0 | AA6: 0 | AB6: 0 | AC6: 0 | AD6: 0 | AE6: 0 | AF6: 0 | AG6: 0 | AH6: 0 | AI6: A demander | AJ6: A demander | AK6: A demander | AL6: 0 | AM6: 0 | AO6: A demander | AP6: A demander | AR6: 1 | AU6: 1 | AV6: 1 | BI6: 0 | BJ6: 0 | BK6: 0 | BL6: 0 | BM6: 0 | BN6: 0 | BO6: 0
B7: Bloc A | C7: Junior | D7: 203 | E7: 1 | F7: 1 | G7: 1 | H7: 1 | I7: 1 | J7: A demander | L7: 1 | N7: A demander | P7: 0 | Q7: 1 | R7: À demander | S7: A demander | T7: 0 | U7: A demander | V7: 0 | W7: 0 | X7: 0 | Y7: 0 | Z7: 0 | AA7: 0 | AB7: 0 | AC7: 0 | AD7: 0 | AE7: 0 | AF7: 0 | AG7: 0 | AH7: 0 | AI7: A demander | AJ7: A demander | AK7: A demander | AL7: 0 | AM7: 0 | AO7: A demander | AP7: A demander | AR7: 1 | AU7: 1 | AV7: 1 | BI7: 0 | BJ7: 0 | BK7: 0 | BL7: 0 | BM7: 0 | BN7: 0 | BO7: 0
B8: Bloc A | C8: Standard | D8: 204 | E8: 1 | F8: 1 | G8: 1 | H8: 1 | I8: 1 | J8: A demander | L8: 1 | M8: 1 | N8: A demander | O8: 1 | P8: 1 | Q8: 1 | R8: À demander | S8: A demander | T8: 0 | U8: A demander | V8: 0 | W8: 0 | X8: 0 | Y8: 0 | Z8: 0 | AA8: 0 | AB8: 0 | AC8: 0 | AD8: 0 | AE8: 0 | AF8: 0 | AG8: 0 | AH8: 0 | AI8: A demander | AJ8: A demander | AK8: A demander | AL8: 0 | AM8: 0 | AO8: A demander | AP8: A demander | AR8: 1 | AU8: 1 | AV8: 1 | BI8: 0 | BJ8: 0 | BK8: 0 | BL8: 0 | BM8: 0 | BN8: 0 | BO8: 0
B9: Bloc A | C9: Standard | D9: 205 | E9: 1 | F9: 1 | G9: 1 | H9: 1 | I9: 1 | J9: A demander | L9: 1 | M9: 1 | N9: A demander | O9: 1 | P9: 1 | Q9: 1 | R9: À demander | S9: A demander | T9: 0 | U9: A demander | V9: 0 | W9: 0 | X9: 0 | Y9: 0 | Z9: 0 | AA9: 0 | AB9: 0 | AC9: 0 | AD9: 0 | AE9: 0 | AF9: 0 | AG9: 0 | AH9: 0 | AI9: A demander | AJ9: A demander | AK9: A demander | AL9: 0 | AM9: 0 | AO9: A demander | AP9: A demander | AR9: 1 | AU9: 1 | AV9: 1 | BI9: 0 | BJ9: 0 | BK9: 0 | BL9: 0 | BM9: 0 | BN9: 0 | BO9: 0
B10: Bloc A | C10: Junior | D10: 206 | E10: 1 | F10: 1 | G10: 1 | H10: 1 | I10: 1 | J10: A demander | L10: 1 | M10: 1 | N10: A demander | O10: 1 | P10: 1 | Q10: 1 | R10: À demander | S10: A demander | T10: 0 | U10: A demander | V10: 0 | W10: 0 | X10: 0 | Y10: 0 | Z10: 0 | AA10: 0 | AB10: 0 | AC10: 0 | AD10: 0 | AE10: 0 | AF10: 0 | AG10: 0 | AH10: 0 | AI10: A demander | AJ10: A demander | AK10: A demander | AL10: 0 | AM10: 0 | AO10: A demander | AP10: A demander | AR10: 1 | AU10: 1 | AV10: 1 | BI10: 0 | BJ10: 0 | BK10: 0 | BL10: 0 | BM10: 0 | BN10: 0 | BO10: 0
B11: Bloc A | C11: Standard | D11: 207 | E11: 1 | F11: 1 | G11: 1 | H11: 1 | I11: 1 | J11: A demander | L11: 1 | M11: 1 | N11: A demander | O11: 1 | P11: 1 | Q11: 1 | R11: À demander | S11: A demander | T11: 0 | U11: A demander | V11: 0 | W11: 0 | X11: 0 | Y11: 0 | Z11: 0 | AA11: 0 | AB11: 0 | AC11: 0 | AD11: 0 | AE11: 0 | AF11: 0 | AG11: 0 | AH11: 0 | AI11: A demander | AJ11: A demander | AK11: A demander | AL11: 0 | AM11: 0 | AO11: A demander | AP11: A demander | AR11: 1 | AU11: 1 | AV11: 1 | BI11: 0 | BJ11: 0 | BK11: 0 | BL11: 0 | BM11: 0 | BN11: 0 | BO11: 0
B12: Bloc A | C12: Standard | D12: 218 | E12: 1 | F12: 1 | G12: 1 | H12: 1 | I12: 1 | J12: A demander | L12: 1 | M12: 1 | N12: A demander | O12: 1 | P12: 1 | Q12: 1 | R12: À demander | S12: A demander | T12: 0 | U12: A demander | V12: 0 | W12: 0 | X12: 0 | Y12: 0 | Z12: 0 | AA12: 0 | AB12: 0 | AC12: 0 | AD12: 0 | AE12: 0 | AF12: 0 | AG12: 0 | AH12: 0 | AI12: A demander | AJ12: A demander | AK12: A demander | AL12: 0 | AM12: 0 | AO12: A demander | AP12: A demander | AR12: 1 | AU12: 1 | AV12: 1 | BI12: 0 | BJ12: 0 | BK12: 0 | BL12: 0 | BM12: 0 | BN12: 0 | BO12: 0
B13: Bloc A | C13: Standard | D13: 219 | E13: 1 | F13: 1 | G13: 1 | H13: 1 | I13: 1 | J13: A demander | L13: 1 | M13: 1 | N13: A demander | O13: 1 | P13: 1 | Q13: 1 | R13: À demander | S13: A demander | T13: 0 | U13: A demander | V13: 0 | W13: 0 | X13: 0 | Y13: 0 | Z13: 0 | AA13: 0 | AB13: 0 | AC13: 0 | AD13: 0 | AE13: 0 | AF13: 0 | AG13: 0 | AH13: 0 | AI13: A demander | AJ13: A demander | AK13: A demander | AL13: 0 | AM13: 0 | AO13: A demander | AP13: A demander | AR13: 1 | AU13: 1 | AV13: 1 | BI13: 0 | BJ13: 0 | BK13: 0 | BL13: 0 | BM13: 0 | BN13: 0 | BO13: 0
B14: Bloc A | C14: Standard | D14: 220 | E14: 1 | F14: 1 | G14: 1 | H14: 1 | I14: 1 | J14: A demander | L14: 1 | M14: 1 | N14: A demander | O14: 1 | P14: 1 | Q14: 1 | R14: À demander | S14: A demander | T14: 0 | U14: A demander | V14: 0 | W14: 0 | X14: 0 | Y14: 0 | Z14: 0 | AA14: 0 | AB14: 0 | AC14: 0 | AD14: 0 | AE14: 0 | AF14: 0 | AG14: 0 | AH14: 0 | AI14: A demander | AJ14: A demander | AK14: A demander | AL14: 0 | AM14: 0 | AO14: A demander | AP14: A demander | AR14: 1 | AU14: 1 | AV14: 1 | BI14: 0 | BJ14: 0 | BK14: 0 | BL14: 0 | BM14: 0 | BN14: 0 | BO14: 0
B15: Bloc A | C15: Junior | D15: 235 | E15: 1 | F15: 1 | G15: 1 | H15: 1 | I15: 1 | J15: A demander | L15: 1 | N15: A demander | P15: 0 | Q15: 1 | R15: À demander | S15: A demander | T15: 0 | U15: A demander | V15: 0 | W15: 0 | X15: 0 | Y15: 0 | Z15: 0 | AA15: 0 | AB15: 0 | AC15: 0 | AD15: 0 | AE15: 0 | AF15: 0 | AG15: 0 | AH15: 0 | AI15: A demander | AJ15: A demander | AK15: A demander | AL15: 0 | AM15: 0 | AO15: A demander | AP15: A demander | AR15: 1 | AU15: 1 | AV15: 1 | BI15: 0 | BJ15: 0 | BK15: 0 | BL15: 0 | BM15: 0 | BN15: 0 | BO15: 0
B16: Bloc A | C16: Standard | D16: 236 | E16: 1 | F16: 1 | G16: 1 | H16: 1 | I16: 1 | J16: A demander | L16: 1 | N16: A demander | P16: 0 | Q16: 1 | R16: À demander | S16: A demander | T16: 0 | U16: A demander | V16: 0 | W16: 0 | X16: 0 | Y16: 0 | Z16: 0 | AA16: 0 | AB16: 0 | AC16: 0 | AD16: 0 | AE16: 0 | AF16: 0 | AG16: 0 | AH16: 0 | AI16: A demander | AJ16: A demander | AK16: A demander | AL16: 0 | AM16: 0 | AO16: A demander | AP16: A demander | AR16: 1 | AU16: 1 | AV16: 1 | BI16: 0 | BJ16: 0 | BK16: 0 | BL16: 0 | BM16: 0 | BN16: 0 | BO16: 0
B17: Bloc A | C17: Standard | D17: 237 | E17: 1 | F17: 1 | G17: 1 | H17: 1 | I17: 1 | J17: A demander | L17: 1 | M17: 1 | N17: A demander | O17: 1 | P17: 1 | Q17: 1 | R17: À demander | S17: A demander | T17: 0 | U17: A demander | V17: 0 | W17: 0 | X17: 0 | Y17: 0 | Z17: 0 | AA17: 0 | AB17: 0 | AC17: 0 | AD17: 0 | AE17: 0 | AF17: 0 | AG17: 0 | AH17: 0 | AI17: A demander | AJ17: A demander | AK17: A demander | AL17: 0 | AM17: 0 | AO17: A demander | AP17: A demander | AR17: 1 | AU17: 1 | AV17: 1 | BI17: 0 | BJ17: 0 | BK17: 0 | BL17: 0 | BM17: 0 | BN17: 0 | BO17: 0
B18: Bloc A | C18: Standard | D18: 238 | E18: 1 | F18: 1 | G18: 1 | H18: 1 | I18: 1 | J18: A demander | L18: 1 | M18: 1 | N18: A demander | O18: 1 | P18: 1 | Q18: 1 | R18: À demander | S18: A demander | T18: 0 | U18: A demander | V18: 0 | W18: 0 | X18: 0 | Y18: 0 | Z18: 0 | AA18: 0 | AB18: 0 | AC18: 0 | AD18: 0 | AE18: 0 | AF18: 0 | AG18: 0 | AH18: 0 | AI18: A demander | AJ18: A demander | AK18: A demander | AL18: 0 | AM18: 0 | AO18: A demander | AP18: A demander | AR18: 1 | AU18: 1 | AV18: 1 | BI18: 0 | BJ18: 0 | BK18: 0 | BL18: 0 | BM18: 0 | BN18: 0 | BO18: 0
B19: Bloc A | C19: Standard | D19: 239 | E19: 1 | F19: 1 | G19: 1 | H19: 1 | I19: 1 | J19: A demander | L19: 1 | M19: 1 | N19: A demander | O19: 1 | P19: 1 | Q19: 1 | R19: À demander | S19: A demander | T19: 0 | U19: A demander | V19: 0 | W19: 0 | X19: 0 | Y19: 0 | Z19: 0 | AA19: 0 | AB19: 0 | AC19: 0 | AD19: 0 | AE19: 0 | AF19: 0 | AG19: 0 | AH19: 0 | AI19: A demander | AJ19: A demander | AK19: A demander | AL19: 0 | AM19: 0 | AO19: A demander | AP19: A demander | AR19: 1 | AU19: 1 | AV19: 1 | BI19: 0 | BJ19: 0 | BK19: 0 | BL19: 0 | BM19: 0 | BN19: 0 | BO19: 0
B20: Bloc A | C20: Standard | D20: 240 | E20: 1 | F20: 1 | G20: 1 | H20: 1 | I20: 1 | J20: A demander | L20: 1 | M20: 1 | N20: A demander | O20: 1 | P20: 1 | Q20: 1 | R20: À demander | S20: A demander | T20: 0 | U20: A demander | V20: 0 | W20: 0 | X20: 0 | Y20: 0 | Z20: 0 | AA20: 0 | AB20: 0 | AC20: 0 | AD20: 0 | AE20: 0 | AF20: 0 | AG20: 0 | AH20: 0 | AI20: A demander | AJ20: A demander | AK20: A demander | AL20: 0 | AM20: 0 | AO20: A demander | AP20: A demander | AR20: 1 | AU20: 1 | AV20: 1 | BI20: 0 | BJ20: 0 | BK20: 0 | BL20: 0 | BM20: 0 | BN20: 0 | BO20: 0
B21: Bloc B | C21: Standard | D21: 208 | E21: 1 | F21: 1 | G21: 1 | H21: 1 | I21: 1 | J21: A demander | L21: 1 | M21: 1 | N21: A demander | O21: 1 | P21: 1 | Q21: 1 | R21: À demander | S21: A demander | T21: 0 | U21: A demander | V21: 0 | W21: 0 | X21: 0 | Y21: 0 | Z21: 0 | AA21: 0 | AB21: 0 | AC21: 0 | AD21: 0 | AE21: 0 | AF21: 0 | AG21: 0 | AH21: 0 | AI21: A demander | AJ21: A demander | AK21: A demander | AL21: 0 | AM21: 0 | AO21: A demander | AP21: A demander | AR21: 1 | AU21: 1 | AV21: 1 | BI21: 0 | BJ21: 0 | BK21: 0 | BL21: 0 | BM21: 0 | BN21: 0 | BO21: 0
B22: Bloc B | C22: Junior | D22: 209 | E22: 1 | F22: 1 | G22: 1 | H22: 1 | I22: 1 | J22: A demander | L22: 1 | M22: 1 | N22: A demander | O22: 1 | P22: 1 | Q22: 1 | R22: À demander | S22: A demander | T22: 0 | U22: A demander | V22: 0 | W22: 0 | X22: 0 | Y22: 0 | Z22: 0 | AA22: 0 | AB22: 0 | AC22: 0 | AD22: 0 | AE22: 0 | AF22: 0 | AG22: 0 | AH22: 0 | AI22: A demander | AJ22: A demander | AK22: A demander | AL22: 0 | AM22: 0 | AO22: A demander | AP22: A demander | AR22: 1 | AU22: 1 | AV22: 1 | BI22: 0 | BJ22: 0 | BK22: 0 | BL22: 0 | BM22: 0 | BN22: 0 | BO22: 0
B23: Bloc B | C23: Junior | D23: 210 | E23: 1 | F23: 1 | G23: 1 | H23: 1 | I23: 1 | J23: A demander | L23: 1 | M23: 1 | N23: A demander | P23: 0.3 | Q23: 1 | R23: À demander | S23: A demander | T23: 0 | U23: A demander | V23: 0 | W23: 0 | X23: 0 | Y23: 0 | Z23: 0 | AA23: 0 | AB23: 0 | AC23: 0 | AD23: 0 | AE23: 0 | AF23: 0 | AG23: 0 | AH23: 0 | AI23: A demander | AJ23: A demander | AK23: A demander | AL23: 0 | AM23: 0 | AO23: A demander | AP23: A demander | AR23: 1 | AU23: 1 | AV23: 1 | BI23: 0 | BJ23: 0 | BK23: 0 | BL23: 0 | BM23: 0 | BN23: 0 | BO23: 0
B24: Bloc B | C24: Standard | D24: 211 | E24: 1 | F24: 1 | G24: 1 | H24: 1 | I24: 1 | J24: A demander | L24: 1 | M24: 1 | N24: A demander | P24: 0.8 | Q24: 1 | R24: À demander | S24: A demander | T24: 0 | U24: A demander | V24: 0 | W24: 0 | X24: 0 | Y24: 0 | Z24: 0 | AA24: 0 | AB24: 0 | AC24: 0 | AD24: 0 | AE24: 0 | AF24: 0 | AG24: 0 | AH24: 0 | AI24: A demander | AJ24: A demander | AK24: A demander | AL24: 0 | AM24: 0 | AO24: A demander | AP24: A demander | AR24: 1 | AU24: 1 | AV24: 1 | BI24: 0 | BJ24: 0 | BK24: 0 | BL24: 0 | BM24: 0 | BN24: 0 | BO24: 0
B25: Bloc B | C25: Junior | D25: 212 | E25: 1 | F25: 1 | G25: 1 | H25: 1 | I25: 1 | J25: A demander | L25: 1 | M25: 1 | N25: A demander | O25: 1 | P25: 1 | Q25: 1 | R25: À demander | S25: A demander | T25: 0 | U25: A demander | V25: 0 | W25: 0 | X25: 0 | Y25: 0 | Z25: 0 | AA25: 0 | AB25: 0 | AC25: 0 | AD25: 0 | AE25: 0 | AF25: 0 | AG25: 0 | AH25: 0 | AI25: A demander | AJ25: A demander | AK25: A demander | AL25: 0 | AM25: 0 | AO25: A demander | AP25: A demander | AR25: 1 | AU25: 1 | AV25: 1 | BI25: 0 | BJ25: 0 | BK25: 0 | BL25: 0 | BM25: 0 | BN25: 0 | BO25: 0
B26: Bloc B | C26: Standard | D26: 213 | E26: 1 | F26: 1 | G26: 1 | H26: 1 | I26: 1 | J26: A demander | L26: 1 | M26: 1 | N26: A demander | O26: 1 | P26: 1 | Q26: 1 | R26: À demander | S26: A demander | T26: 0 | U26: A demander | V26: 0 | W26: 0 | X26: 0 | Y26: 0 | Z26: 0 | AA26: 0 | AB26: 0 | AC26: 0 | AD26: 0 | AE26: 0 | AF26: 0 | AG26: 0 | AH26: 0 | AI26: A demander | AJ26: A demander | AK26: A demander | AL26: 0 | AM26: 0 | AO26: A demander | AP26: A demander | AR26: 1 | AU26: 1 | AV26: 1 | BI26: 0 | BJ26: 0 | BK26: 0 | BL26: 0 | BM26: 0 | BN26: 0 | BO26: 0
B27: Bloc B | C27: Executive | D27: 214 | E27: 1 | F27: 1 | G27: 1 | H27: 1 | I27: 1 | J27: A demander | K27: 0.8 | L27: 1 | M27: 1 | N27: A demander | O27: 0 | P27: 0 | Q27: 0 | R27: À demander | S27: A demander | T27: 0 | U27: A demander | V27: 0 | W27: 0 | X27: 0 | Y27: 0 | Z27: 0 | AA27: 0 | AB27: 0 | AC27: 0 | AD27: 0 | AE27: 0 | AF27: 0 | AG27: 0 | AH27: 0 | AI27: A demander | AJ27: A demander | AK27: A demander | AL27: 0 | AM27: 0 | AN27: 0.8 | AO27: A demander | AP27: A demander | AQ27: 0.8 | AR27: 1 | AS27: 0.3 | AT27: 1 | AU27: 1 | AV27: 1 | AX27: 0.3 | AY27: 0 | AZ27: 0 | BA27: 0 | BI27: 0 | BJ27: 0 | BK27: 0 | BL27: 0 | BM27: 0 | BN27: 0 | BO27: 0
B28: Bloc B | C28: Standard | D28: 215 | E28: 1 | F28: 1 | G28: 1 | H28: 1 | I28: 1 | J28: A demander | K28: 0.9 | L28: 1 | M28: Je sais pas | N28: A demander | O28: 0.3 | P28: 0 | Q28: 0 | R28: À demander | S28: A demander | T28: 0 | U28: A demander | V28: 0 | W28: 0 | X28: 0 | Y28: 0 | Z28: 0 | AA28: 0 | AB28: 0 | AC28: 0 | AD28: 0 | AE28: 0 | AF28: 0 | AG28: 0 | AH28: 0 | AI28: A demander | AJ28: A demander | AK28: A demander | AL28: 0 | AM28: 0 | AN28: 0.85 | AO28: 1 | AP28: A demander | AQ28: 0.6 | AR28: 0 | AS28: 0.8 | AT28: 1 | AU28: 1 | AV28: 1 | AW28: À demander | AX28: 0.55 | AY28: 0.3 | AZ28: 0 | BA28: 1 | BB28: 0 | BC28: 0 | BD28: 0 | BE28: Bande sur ba13 oui | BG28: 0 | BH28: 0 | BI28: 0 | BJ28: 0 | BK28: 0 | BL28: 0 | BM28: 0 | BN28: 0 | BO28: 0
B29: Bloc B | C29: Standard | D29: 216 | E29: 1 | F29: 1 | G29: 1 | H29: 1 | I29: 1 | J29: A demander | K29: 0.8 | L29: 1 | M29: 1 | N29: A demander | O29: 0.3 | P29: 0 | Q29: 0 | R29: À demander | S29: A demander | T29: 0 | U29: A demander | V29: 0 | W29: 0 | X29: 0 | Y29: 0 | Z29: 0 | AA29: 0 | AB29: 0 | AC29: 0 | AD29: 0 | AE29: 0 | AF29: 0 | AG29: 0 | AH29: 0 | AI29: A demander | AJ29: A demander | AK29: A demander | AL29: 0 | AM29: 0 | AN29: 0.85 | AO29: 1 | AP29: A demander | AQ29: 0.7 | AR29: 0 | AS29: 1 | AT29: 1 | AU29: 1 | AV29: 1 | AW29: À demander | AX29: 0.7 | AY29: 0.7 | AZ29: 0 | BA29: 1 | BB29: 0 | BC29: 0 | BD29: 0.5 | BE29: Bande sur ba13 oui | BG29: 0 | BH29: 0 | BI29: 0 | BJ29: 0 | BK29: 0 | BL29: 0 | BM29: 0 | BN29: 0 | BO29: 0 | BS29: 0 | BT29: 0
B30: Bloc B | C30: Junior | D30: 217 | E30: 1 | F30: 1 | G30: 1 | H30: 1 | I30: 1 | J30: A demander | K30: 0.8 | L30: 0 | M30: 0 | N30: A demander | O30: 0 | P30: 0 | Q30: 0 | R30: À demander | S30: A demander | T30: 0 | U30: A demander | V30: 0 | W30: 0 | X30: 0 | Y30: 0 | Z30: 0 | AA30: 0 | AB30: 0 | AC30: 0 | AD30: 0 | AE30: 0 | AF30: 0 | AG30: 0 | AH30: 0 | AI30: A demander | AJ30: A demander | AK30: A demander | AL30: 0 | AM30: 0 | AN30: 1 | AO30: 1 | AP30: A demander | AQ30: 0.6 | AR30: 1 | AS30: 1 | AT30: 1 | AU30: 1 | AV30: 1 | AW30: À demander | AX30: 0 | AY30: 0 | AZ30: 0 | BA30: 1 | BB30: 0 | BC30: 0 | BD30: 0.5 | BE30: 1 | BF30: 1 | BG30: 0 | BH30: 0 | BI30: 0 | BJ30: 0 | BK30: 0 | BL30: 0 | BM30: 0 | BN30: 0 | BO30: 0 | BP30: 0 | BQ30: 0 | BR30: 0 | BS30: 0 | BT30: 0
B31: Bloc B | C31: Standard | D31: 221 | E31: 1 | F31: 1 | G31: 1 | H31: 1 | I31: 1 | J31: A demander | L31: 1 | N31: A demander | P31: 0 | Q31: 1 | R31: À demander | S31: A demander | T31: 0 | U31: A demander | V31: 0 | W31: 0 | X31: 0 | Y31: 0 | Z31: 0 | AA31: 0 | AB31: 0 | AC31: 0 | AD31: 0 | AE31: 0 | AF31: 0 | AG31: 0 | AH31: 0 | AI31: A demander | AJ31: A demander | AK31: A demander | AL31: 0 | AM31: 0 | AO31: A demander | AP31: A demander | AR31: 1 | AU31: 1 | AV31: 1 | BI31: 0 | BJ31: 0 | BK31: 0 | BL31: 0 | BM31: 0 | BN31: 0 | BO31: 0
B32: Bloc B | C32: Standard | D32: 222 | E32: 1 | F32: 1 | G32: 1 | H32: 1 | I32: 1 | J32: A demander | L32: 1 | M32: 1 | N32: A demander | O32: 1 | P32: 1 | Q32: 1 | R32: À demander | S32: A demander | T32: 0 | U32: A demander | V32: 0 | W32: 0 | X32: 0 | Y32: 0 | Z32: 0 | AA32: 0 | AB32: 0 | AC32: 0 | AD32: 0 | AE32: 0 | AF32: 0 | AG32: 0 | AH32: 0 | AI32: A demander | AJ32: A demander | AK32: A demander | AL32: 0 | AM32: 0 | AO32: A demander | AP32: A demander | AR32: 1 | AU32: 1 | AV32: 1 | BI32: 0 | BJ32: 0 | BK32: 0 | BL32: 0 | BM32: 0 | BN32: 0 | BO32: 0
B33: Bloc C | C33: Standard | D33: 223 | E33: 1 | F33: 1 | G33: 1 | H33: 1 | I33: 1 | J33: A demander | L33: 1 | N33: A demander | P33: 0 | Q33: 1 | R33: À demander | S33: A demander | T33: 0 | U33: A demander | V33: 0 | W33: 0 | X33: 0 | Y33: 0 | Z33: 0 | AA33: 0 | AB33: 0 | AC33: 0 | AD33: 0 | AE33: 0 | AF33: 0 | AG33: 0 | AH33: 0 | AI33: A demander | AJ33: A demander | AK33: A demander | AL33: 0 | AM33: 0 | AO33: A demander | AP33: A demander | AR33: 1 | AS33: 1 | AT33: 1 | AU33: 1 | AV33: 1 | AX33: 1 | AY33: 1 | AZ33: 1 | BA33: 1 | BB33: 0 | BC33: 0 | BD33: 0.5 | BE33: 1 | BF33: 0 | BG33: 0 | BI33: 0 | BJ33: 0 | BK33: 0 | BL33: 0 | BM33: 0 | BN33: 0 | BO33: 0
B34: Bloc C | C34: Standard | D34: 224 | E34: 1 | F34: 1 | G34: 1 | H34: 1 | I34: 1 | J34: A demander | L34: 1 | N34: A demander | P34: 0 | Q34: 1 | R34: À demander | S34: A demander | T34: 0 | U34: A demander | V34: 0 | W34: 0 | X34: 0 | Y34: 0 | Z34: 0 | AA34: 0 | AB34: 0 | AC34: 0 | AD34: 0 | AE34: 0 | AF34: 0 | AG34: 0 | AH34: 0 | AI34: A demander | AJ34: A demander | AK34: A demander | AL34: 0 | AM34: 0 | AO34: A demander | AP34: A demander | AR34: 1 | AS34: 1 | AT34: 1 | AU34: 1 | AV34: 1 | AX34: 1 | AY34: 1 | AZ34: 1 | BA34: 1 | BB34: 0 | BC34: 0 | BD34: 1 | BE34: 1 | BF34: 0 | BG34: 0 | BI34: 0 | BJ34: 0 | BK34: 0 | BL34: 0 | BM34: 0 | BN34: 0 | BO34: 0
B35: Bloc C | C35: Standard | D35: 225 | E35: 1 | F35: 1 | G35: 1 | H35: 1 | I35: 1 | J35: A demander | L35: 1 | N35: A demander | P35: 0 | Q35: 1 | R35: À demander | S35: A demander | T35: 0 | U35: A demander | V35: 0 | W35: 0 | X35: 0 | Y35: 0 | Z35: 0 | AA35: 0 | AB35: 0 | AC35: 0 | AD35: 0 | AE35: 0 | AF35: 0 | AG35: 0 | AH35: 0 | AI35: A demander | AJ35: A demander | AK35: A demander | AL35: 0 | AM35: 0 | AO35: A demander | AP35: A demander | AR35: 1 | AS35: 1 | AT35: 1 | AU35: 1 | AV35: 1 | AX35: 1 | AY35: 1 | AZ35: 1 | BA35: 1 | BB35: 0 | BC35: 0 | BD35: 1 | BE35: 1 | BF35: 0 | BG35: 0 | BI35: 0 | BJ35: 0 | BK35: 0 | BL35: 0 | BM35: 0 | BN35: 0 | BO35: 0
B36: Bloc C | C36: Standard | D36: 226 | E36: 1 | F36: 1 | G36: 1 | H36: 1 | I36: 1 | J36: A demander | L36: 1 | N36: A demander | P36: 0 | Q36: 1 | R36: À demander | S36: A demander | T36: 0 | U36: A demander | V36: 0 | W36: 0 | X36: 0 | Y36: 0 | Z36: 0 | AA36: 0 | AB36: 0 | AC36: 0 | AD36: 0 | AE36: 0 | AF36: 0 | AG36: 0 | AH36: 0 | AI36: A demander | AJ36: A demander | AK36: A demander | AL36: 0 | AM36: 0 | AO36: A demander | AP36: A demander | AR36: 1 | AS36: 1 | AT36: 1 | AU36: 1 | AV36: 1 | AX36: 1 | AY36: 1 | AZ36: 1 | BA36: 1 | BB36: 0 | BC36: 0 | BD36: 1 | BE36: 1 | BF36: 0 | BG36: 0 | BI36: 0 | BJ36: 0 | BK36: 0 | BL36: 0 | BM36: 0 | BN36: 0 | BO36: 0
B37: Bloc C | C37: Junior | D37: 227 | E37: 1 | F37: 1 | G37: 1 | H37: 1 | I37: 1 | J37: A demander | L37: 1 | M37: 1 | N37: A demander | O37: 1 | P37: 1 | Q37: 1 | R37: À demander | S37: A demander | T37: 1 | U37: A demander | V37: 1 | W37: 1 | X37: 1 | Y37: 1 | Z37: 1 | AA37: 1 | AB37: 0 | AC37: 0 | AD37: 1 | AE37: 1 | AF37: 1 | AG37: 1 | AH37: 1 | AI37: A demander | AJ37: A demander | AK37: A demander | AN37: 1 | AO37: 1 | AP37: 1 | AQ37: 1 | AR37: 1 | AU37: 1 | AV37: 1 | AX37: 1 | AY37: 1 | AZ37: 1 | BA37: 1 | BB37: 0 | BC37: 0 | BD37: 0.5 | BE37: 0 | BF37: 0 | BG37: 0 | BI37: 1 | BJ37: 1 | BK37: 0 | BL37: 0 | BM37: 0 | BN37: 0 | BO37: 0
B38: Bloc C | C38: Standard | D38: 228 | E38: 1 | F38: 1 | G38: 1 | H38: 1 | I38: 1 | J38: A demander | L38: 1 | M38: 1 | N38: A demander | O38: 1 | P38: 1 | Q38: 1 | R38: À demander | S38: A demander | T38: 1 | U38: A demander | V38: 1 | W38: 1 | X38: 1 | Y38: 1 | Z38: 1 | AA38: 1 | AB38: 0 | AC38: 0 | AD38: 1 | AE38: 1 | AF38: 1 | AG38: 1 | AH38: 1 | AI38: A demander | AJ38: A demander | AK38: A demander | AN38: 1 | AO38: 1 | AP38: 1 | AQ38: 1 | AR38: 1 | AU38: 1 | AV38: 1 | BI38: 1 | BJ38: 1 | BK38: 0 | BL38: 0 | BM38: 0 | BN38: 0 | BO38: 0
B39: Bloc C | C39: Standard | D39: 229 | E39: 1 | F39: 1 | G39: 1 | H39: 1 | I39: 1 | J39: A demander | L39: 1 | N39: A demander | P39: 0 | Q39: 1 | R39: À demander | S39: A demander | T39: 0 | U39: A demander | V39: 0 | W39: 0 | X39: 0 | Y39: 0 | Z39: 0 | AA39: 0 | AB39: 0 | AC39: 0 | AD39: 0 | AE39: 0 | AF39: 0 | AG39: 0 | AH39: 0 | AI39: A demander | AJ39: A demander | AK39: A demander | AL39: 0 | AM39: 0 | AO39: A demander | AP39: A demander | AR39: 1 | AU39: 1 | AV39: 1 | BI39: 0 | BJ39: 0 | BK39: 0 | BL39: 0 | BM39: 0 | BN39: 0 | BO39: 0
B40: Bloc C | C40: Standard | D40: 230 | E40: 1 | F40: 1 | G40: 1 | H40: 1 | I40: 1 | J40: A demander | L40: 1 | M40: 1 | N40: A demander | O40: 1 | P40: 1 | Q40: 1 | R40: À demander | S40: A demander | T40: 0 | U40: A demander | V40: 0 | W40: 0 | X40: 0 | Y40: 0 | Z40: 0 | AA40: 0 | AB40: 0 | AC40: 0 | AD40: 0 | AE40: 0 | AF40: 0 | AG40: 0 | AH40: 0 | AI40: A demander | AJ40: A demander | AK40: A demander | AL40: 0 | AM40: 0 | AO40: A demander | AP40: A demander | AR40: 1 | AU40: 1 | AV40: 1 | BI40: 0 | BJ40: 0 | BK40: 0 | BL40: 0 | BM40: 0 | BN40: 0 | BO40: 0
...

Sheet Graphes SDB
A1: GRAPHES SDB
A3: PLOMBERIE SOL | I3: CLOISONS | Q3: ÉLECTRICITÉ CLOISONS
A4: R+2 | B4: =IFERROR(SUM('Suivi des Chambres'!E5:G44)/(COUNT('Suivi des Chambres'!$D$5:$D$44)*COLUMNS('Suivi des Chambres'!E:G)),0) -> 1 | G4: =B4 -> 1 | I4: R+2 | J4: =IFERROR(SUM('Suivi des Chambres'!H5:H44)/(COUNT('Suivi des Chambres'!$D$5:$D$44)*COLUMNS('Suivi des Chambres'!H:H)),0) -> 1 | O4: =J4 -> 1 | Q4: R+2 | R4: =IFERROR(SUM('Suivi des Chambres'!I5:K44)/(COUNT('Suivi des Chambres'!$D$5:$D$44)*COLUMNS('Suivi des Chambres'!I:K)),0) -> 0.36083333 | W4: =R4 -> 0.36083333
A5: R+3 | B5: =IFERROR(SUM('Suivi des Chambres'!E45:G84)/(COUNT('Suivi des Chambres'!$D$45:$D$84)*COLUMNS('Suivi des Chambres'!E:G)),0) -> 1 | G5: =B5 -> 1 | I5: R+3 | J5: =IFERROR(SUM('Suivi des Chambres'!H45:H84)/(COUNT('Suivi des Chambres'!$D$45:$D$84)*COLUMNS('Suivi des Chambres'!H:H)),0) -> 1 | O5: =J5 -> 1 | Q5: R+3 | R5: =IFERROR(SUM('Suivi des Chambres'!I45:K84)/(COUNT('Suivi des Chambres'!$D$45:$D$84)*COLUMNS('Suivi des Chambres'!I:K)),0) -> 0.33333333 | W5: =R5 -> 0.33333333
A6: R+4 | B6: =IFERROR(SUM('Suivi des Chambres'!E85:G108)/(COUNT('Suivi des Chambres'!$D$85:$D$108)*COLUMNS('Suivi des Chambres'!E:G)),0) -> 1 | G6: =B6 -> 1 | I6: R+4 | J6: =IFERROR(SUM('Suivi des Chambres'!H85:H108)/(COUNT('Suivi des Chambres'!$D$85:$D$108)*COLUMNS('Suivi des Chambres'!H:H)),0) -> 1 | O6: =J6 -> 1 | Q6: R+4 | R6: =IFERROR(SUM('Suivi des Chambres'!I85:K108)/(COUNT('Suivi des Chambres'!$D$85:$D$108)*COLUMNS('Suivi des Chambres'!I:K)),0) -> 0.33333333 | W6: =R6 -> 0.33333333
A7: R+5 | B7: =IFERROR(SUM('Suivi des Chambres'!E109:G132)/(COUNT('Suivi des Chambres'!$D$109:$D$132)*COLUMNS('Suivi des Chambres'!E:G)),0) -> 1 | G7: =B7 -> 1 | I7: R+5 | J7: =IFERROR(SUM('Suivi des Chambres'!H109:H132)/(COUNT('Suivi des Chambres'!$D$109:$D$132)*COLUMNS('Suivi des Chambres'!H:H)),0) -> 1 | O7: =J7 -> 1 | Q7: R+5 | R7: =IFERROR(SUM('Suivi des Chambres'!I109:K132)/(COUNT('Suivi des Chambres'!$D$109:$D$132)*COLUMNS('Suivi des Chambres'!I:K)),0) -> 0.33333333 | W7: =R7 -> 0.33333333
A9: ÉTANCHÉITÉ | I9: DRESSAGE | Q9: CHAPE
A10: R+2 | B10: =IFERROR(SUM('Suivi des Chambres'!L5:N44)/(COUNT('Suivi des Chambres'!$D$5:$D$44)*COLUMNS('Suivi des Chambres'!L:N)),0) -> 0.55 | G10: =B10 -> 0.55 | I10: R+2 | J10: =IFERROR(SUM('Suivi des Chambres'!O5:O44)/(COUNT('Suivi des Chambres'!$D$5:$D$44)*COLUMNS('Suivi des Chambres'!O:O)),0) -> 0.59 | O10: =J10 -> 0.59 | Q10: R+2 | R10: =IFERROR(SUM('Suivi des Chambres'!P5:P44)/(COUNT('Suivi des Chambres'!$D$5:$D$44)*COLUMNS('Suivi des Chambres'!P:P)),0) -> 0.6025 | W10: =R10 -> 0.6025
A11: R+3 | B11: =IFERROR(SUM('Suivi des Chambres'!L45:N84)/(COUNT('Suivi des Chambres'!$D$45:$D$84)*COLUMNS('Suivi des Chambres'!L:N)),0) -> 0.45416667 | G11: =B11 -> 0.45416667 | I11: R+3 | J11: =IFERROR(SUM('Suivi des Chambres'!O45:O84)/(COUNT('Suivi des Chambres'!$D$45:$D$84)*COLUMNS('Suivi des Chambres'!O:O)),0) -> 0.575 | O11: =J11 -> 0.575 | Q11: R+3 | R11: =IFERROR(SUM('Suivi des Chambres'!P45:P84)/(COUNT('Suivi des Chambres'!$D$45:$D$84)*COLUMNS('Suivi des Chambres'!P:P)),0) -> 0.375 | W11: =R11 -> 0.375
A12: R+4 | B12: =IFERROR(SUM('Suivi des Chambres'!L85:N108)/(COUNT('Suivi des Chambres'!$D$85:$D$108)*COLUMNS('Suivi des Chambres'!L:N)),0) -> 0 | G12: =B12 -> 0 | I12: R+4 | J12: =IFERROR(SUM('Suivi des Chambres'!O85:O108)/(COUNT('Suivi des Chambres'!$D$85:$D$108)*COLUMNS('Suivi des Chambres'!O:O)),0) -> 0 | O12: =J12 -> 0 | Q12: R+4 | R12: =IFERROR(SUM('Suivi des Chambres'!P85:P108)/(COUNT('Suivi des Chambres'!$D$85:$D$108)*COLUMNS('Suivi des Chambres'!P:P)),0) -> 0 | W12: =R12 -> 0
A13: R+5 | B13: =IFERROR(SUM('Suivi des Chambres'!L109:N132)/(COUNT('Suivi des Chambres'!$D$109:$D$132)*COLUMNS('Suivi des Chambres'!L:N)),0) -> 0 | G13: =B13 -> 0 | I13: R+5 | J13: =IFERROR(SUM('Suivi des Chambres'!O109:O132)/(COUNT('Suivi des Chambres'!$D$109:$D$132)*COLUMNS('Suivi des Chambres'!O:O)),0) -> 0 | O13: =J13 -> 0 | Q13: R+5 | R13: =IFERROR(SUM('Suivi des Chambres'!P109:P132)/(COUNT('Suivi des Chambres'!$D$109:$D$132)*COLUMNS('Suivi des Chambres'!P:P)),0) -> 0 | W13: =R13 -> 0
A15: FAUX PLAFOND SDB | I15: PEINTURE FP | Q15: REVÊTEMENT MURAL
A16: R+2 | B16: =IFERROR(SUM('Suivi des Chambres'!Q5:W44)/(COUNT('Suivi des Chambres'!$D$5:$D$44)*COLUMNS('Suivi des Chambres'!Q:W)),0) -> 0.15 | G16: =B16 -> 0.15 | I16: R+2 | J16: =IFERROR(SUM('Suivi des Chambres'!X5:X44)/(COUNT('Suivi des Chambres'!$D$5:$D$44)*COLUMNS('Suivi des Chambres'!X:X)),0) -> 0.05 | O16: =J16 -> 0.05 | Q16: R+2 | R16: =IFERROR(SUM('Suivi des Chambres'!Y5:Z44)/(COUNT('Suivi des Chambres'!$D$5:$D$44)*COLUMNS('Suivi des Chambres'!Y:Z)),0) -> 0.05 | W16: =R16 -> 0.05
A17: R+3 | B17: =IFERROR(SUM('Suivi des Chambres'!Q45:W84)/(COUNT('Suivi des Chambres'!$D$45:$D$84)*COLUMNS('Suivi des Chambres'!Q:W)),0) -> 0.14285714 | G17: =B17 -> 0.14285714 | I17: R+3 | J17: =IFERROR(SUM('Suivi des Chambres'!X45:X84)/(COUNT('Suivi des Chambres'!$D$45:$D$84)*COLUMNS('Suivi des Chambres'!X:X)),0) -> 0 | O17: =J17 -> 0 | Q17: R+3 | R17: =IFERROR(SUM('Suivi des Chambres'!Y45:Z84)/(COUNT('Suivi des Chambres'!$D$45:$D$84)*COLUMNS('Suivi des Chambres'!Y:Z)),0) -> 0 | W17: =R17 -> 0
A18: R+4 | B18: =IFERROR(SUM('Suivi des Chambres'!Q85:W108)/(COUNT('Suivi des Chambres'!$D$85:$D$108)*COLUMNS('Suivi des Chambres'!Q:W)),0) -> 0 | G18: =B18 -> 0 | I18: R+4 | J18: =IFERROR(SUM('Suivi des Chambres'!X85:X108)/(COUNT('Suivi des Chambres'!$D$85:$D$108)*COLUMNS('Suivi des Chambres'!X:X)),0) -> 0 | O18: =J18 -> 0 | Q18: R+4 | R18: =IFERROR(SUM('Suivi des Chambres'!Y85:Z108)/(COUNT('Suivi des Chambres'!$D$85:$D$108)*COLUMNS('Suivi des Chambres'!Y:Z)),0) -> 0 | W18: =R18 -> 0
A19: R+5 | B19: =IFERROR(SUM('Suivi des Chambres'!Q109:W132)/(COUNT('Suivi des Chambres'!$D$109:$D$132)*COLUMNS('Suivi des Chambres'!Q:W)),0) -> 0 | G19: =B19 -> 0 | I19: R+5 | J19: =IFERROR(SUM('Suivi des Chambres'!X109:X132)/(COUNT('Suivi des Chambres'!$D$109:$D$132)*COLUMNS('Suivi des Chambres'!X:X)),0) -> 0 | O19: =J19 -> 0 | Q19: R+5 | R19: =IFERROR(SUM('Suivi des Chambres'!Y109:Z132)/(COUNT('Suivi des Chambres'!$D$109:$D$132)*COLUMNS('Suivi des Chambres'!Y:Z)),0) -> 0 | W19: =R19 -> 0
A21: REVÊTEMENT SOL | I21: MENUISERIE ALU | Q21: MENUISERIE BOIS
A22: R+2 | B22: =IFERROR(SUM('Suivi des Chambres'!AA5:AA44)/(COUNT('Suivi des Chambres'!$D$5:$D$44)*COLUMNS('Suivi des Chambres'!AA:AA)),0) -> 0.05 | G22: =B22 -> 0.05 | I22: R+2 | J22: =IFERROR(SUM('Suivi des Chambres'!AB5:AC44)/(COUNT('Suivi des Chambres'!$D$5:$D$44)*COLUMNS('Suivi des Chambres'!AB:AC)),0) -> 0 | O22: =J22 -> 0 | Q22: R+2 | R22: =IFERROR(SUM('Suivi des Chambres'!AD5:AE44)/(COUNT('Suivi des Chambres'!$D$5:$D$44)*COLUMNS('Suivi des Chambres'!AD:AE)),0) -> 0.05 | W22: =R22 -> 0.05
A23: R+3 | B23: =IFERROR(SUM('Suivi des Chambres'!AA45:AA84)/(COUNT('Suivi des Chambres'!$D$45:$D$84)*COLUMNS('Suivi des Chambres'!AA:AA)),0) -> 0 | G23: =B23 -> 0 | I23: R+3 | J23: =IFERROR(SUM('Suivi des Chambres'!AB45:AC84)/(COUNT('Suivi des Chambres'!$D$45:$D$84)*COLUMNS('Suivi des Chambres'!AB:AC)),0) -> 0 | O23: =J23 -> 0 | Q23: R+3 | R23: =IFERROR(SUM('Suivi des Chambres'!AD45:AE84)/(COUNT('Suivi des Chambres'!$D$45:$D$84)*COLUMNS('Suivi des Chambres'!AD:AE)),0) -> 0 | W23: =R23 -> 0
A24: R+4 | B24: =IFERROR(SUM('Suivi des Chambres'!AA85:AA108)/(COUNT('Suivi des Chambres'!$D$85:$D$108)*COLUMNS('Suivi des Chambres'!AA:AA)),0) -> 0 | G24: =B24 -> 0 | I24: R+4 | J24: =IFERROR(SUM('Suivi des Chambres'!AB85:AC108)/(COUNT('Suivi des Chambres'!$D$85:$D$108)*COLUMNS('Suivi des Chambres'!AB:AC)),0) -> 0 | O24: =J24 -> 0 | Q24: R+4 | R24: =IFERROR(SUM('Suivi des Chambres'!AD85:AE108)/(COUNT('Suivi des Chambres'!$D$85:$D$108)*COLUMNS('Suivi des Chambres'!AD:AE)),0) -> 0 | W24: =R24 -> 0
A25: R+5 | B25: =IFERROR(SUM('Suivi des Chambres'!AA109:AA132)/(COUNT('Suivi des Chambres'!$D$109:$D$132)*COLUMNS('Suivi des Chambres'!AA:AA)),0) -> 0 | G25: =B25 -> 0 | I25: R+5 | J25: =IFERROR(SUM('Suivi des Chambres'!AB109:AC132)/(COUNT('Suivi des Chambres'!$D$109:$D$132)*COLUMNS('Suivi des Chambres'!AB:AC)),0) -> 0 | O25: =J25 -> 0 | Q25: R+5 | R25: =IFERROR(SUM('Suivi des Chambres'!AD109:AE132)/(COUNT('Suivi des Chambres'!$D$109:$D$132)*COLUMNS('Suivi des Chambres'!AD:AE)),0) -> 0 | W25: =R25 -> 0
A27: AGENCEMENT | I27: SANITAIRES | Q27: ACCESSOIRES
A28: R+2 | B28: =IFERROR(SUM('Suivi des Chambres'!AF5:AF44)/(COUNT('Suivi des Chambres'!$D$5:$D$44)*COLUMNS('Suivi des Chambres'!AF:AF)),0) -> 0.05 | G28: =B28 -> 0.05 | I28: R+2 | J28: =IFERROR(SUM('Suivi des Chambres'!AG5:AG44)/(COUNT('Suivi des Chambres'!$D$5:$D$44)*COLUMNS('Suivi des Chambres'!AG:AG)),0) -> 0.05 | O28: =J28 -> 0.05 | Q28: R+2 | R28: =IFERROR(SUM('Suivi des Chambres'!AH5:AH44)/(COUNT('Suivi des Chambres'!$D$5:$D$44)*COLUMNS('Suivi des Chambres'!AH:AH)),0) -> 0.05 | W28: =R28 -> 0.05
A29: R+3 | B29: =IFERROR(SUM('Suivi des Chambres'!AF45:AF84)/(COUNT('Suivi des Chambres'!$D$45:$D$84)*COLUMNS('Suivi des Chambres'!AF:AF)),0) -> 0 | G29: =B29 -> 0 | I29: R+3 | J29: =IFERROR(SUM('Suivi des Chambres'!AG45:AG84)/(COUNT('Suivi des Chambres'!$D$45:$D$84)*COLUMNS('Suivi des Chambres'!AG:AG)),0) -> 0 | O29: =J29 -> 0 | Q29: R+3 | R29: =IFERROR(SUM('Suivi des Chambres'!AH45:AH84)/(COUNT('Suivi des Chambres'!$D$45:$D$84)*COLUMNS('Suivi des Chambres'!AH:AH)),0) -> 0 | W29: =R29 -> 0
A30: R+4 | B30: =IFERROR(SUM('Suivi des Chambres'!AF85:AF108)/(COUNT('Suivi des Chambres'!$D$85:$D$108)*COLUMNS('Suivi des Chambres'!AF:AF)),0) -> 0 | G30: =B30 -> 0 | I30: R+4 | J30: =IFERROR(SUM('Suivi des Chambres'!AG85:AG108)/(COUNT('Suivi des Chambres'!$D$85:$D$108)*COLUMNS('Suivi des Chambres'!AG:AG)),0) -> 0 | O30: =J30 -> 0 | Q30: R+4 | R30: =IFERROR(SUM('Suivi des Chambres'!AH85:AH108)/(COUNT('Suivi des Chambres'!$D$85:$D$108)*COLUMNS('Suivi des Chambres'!AH:AH)),0) -> 0 | W30: =R30 -> 0
A31: R+5 | B31: =IFERROR(SUM('Suivi des Chambres'!AF109:AF132)/(COUNT('Suivi des Chambres'!$D$109:$D$132)*COLUMNS('Suivi des Chambres'!AF:AF)),0) -> 0 | G31: =B31 -> 0 | I31: R+5 | J31: =IFERROR(SUM('Suivi des Chambres'!AG109:AG132)/(COUNT('Suivi des Chambres'!$D$109:$D$132)*COLUMNS('Suivi des Chambres'!AG:AG)),0) -> 0 | O31: =J31 -> 0 | Q31: R+5 | R31: =IFERROR(SUM('Suivi des Chambres'!AH109:AH132)/(COUNT('Suivi des Chambres'!$D$109:$D$132)*COLUMNS('Suivi des Chambres'!AH:AH)),0) -> 0 | W31: =R31 -> 0
A33: TESTS | I33: RÉCEPTION
A34: R+2 | B34: =IFERROR(SUM('Suivi des Chambres'!AI5:AK44)/(COUNT('Suivi des Chambres'!$D$5:$D$44)*COLUMNS('Suivi des Chambres'!AI:AK)),0) -> 0 | G34: =B34 -> 0 | I34: R+2 | J34: =IFERROR(SUM('Suivi des Chambres'!AL5:AM44)/(COUNT('Suivi des Chambres'!$D$5:$D$44)*COLUMNS('Suivi des Chambres'!AL:AM)),0) -> 0 | O34: =J34 -> 0
A35: R+3 | B35: =IFERROR(SUM('Suivi des Chambres'!AI45:AK84)/(COUNT('Suivi des Chambres'!$D$45:$D$84)*COLUMNS('Suivi des Chambres'!AI:AK)),0) -> 0 | G35: =B35 -> 0 | I35: R+3 | J35: =IFERROR(SUM('Suivi des Chambres'!AL45:AM84)/(COUNT('Suivi des Chambres'!$D$45:$D$84)*COLUMNS('Suivi des Chambres'!AL:AM)),0) -> 0 | O35: =J35 -> 0
A36: R+4 | B36: =IFERROR(SUM('Suivi des Chambres'!AI85:AK108)/(COUNT('Suivi des Chambres'!$D$85:$D$108)*COLUMNS('Suivi des Chambres'!AI:AK)),0) -> 0 | G36: =B36 -> 0 | I36: R+4 | J36: =IFERROR(SUM('Suivi des Chambres'!AL85:AM108)/(COUNT('Suivi des Chambres'!$D$85:$D$108)*COLUMNS('Suivi des Chambres'!AL:AM)),0) -> 0 | O36: =J36 -> 0
A37: R+5 | B37: =IFERROR(SUM('Suivi des Chambres'!AI109:AK132)/(COUNT('Suivi des Chambres'!$D$109:$D$132)*COLUMNS('Suivi des Chambres'!AI:AK)),0) -> 0 | G37: =B37 -> 0 | I37: R+5 | J37: =IFERROR(SUM('Suivi des Chambres'!AL109:AM132)/(COUNT('Suivi des Chambres'!$D$109:$D$132)*COLUMNS('Suivi des Chambres'!AL:AM)),0) -> 0 | O37: =J37 -> 0

Sheet Graphes Chambre
A1: GRAPHES CHAMBRE
A3: CLOISONS | I3: ÉLECTRICITÉ CLOISONS | Q3: CHAPE
A4: R+2 | B4: =IFERROR(SUM('Suivi des Chambres'!AN5:AN44)/(COUNT('Suivi des Chambres'!$D$5:$D$44)*COLUMNS('Suivi des Chambres'!AN:AN)),0) -> 0.1375 | G4: =B4 -> 0.1375 | I4: R+2 | J4: =IFERROR(SUM('Suivi des Chambres'!AO5:AQ44)/(COUNT('Suivi des Chambres'!$D$5:$D$44)*COLUMNS('Suivi des Chambres'!AO:AQ)),0) -> 0.0975 | O4: =J4 -> 0.0975 | Q4: R+2 | R4: =IFERROR(SUM('Suivi des Chambres'!AR5:AR44)/(COUNT('Suivi des Chambres'!$D$5:$D$44)*COLUMNS('Suivi des Chambres'!AR:AR)),0) -> 0.95 | W4: =R4 -> 0.95
A5: R+3 | B5: =IFERROR(SUM('Suivi des Chambres'!AN45:AN84)/(COUNT('Suivi des Chambres'!$D$45:$D$84)*COLUMNS('Suivi des Chambres'!AN:AN)),0) -> 0 | G5: =B5 -> 0 | I5: R+3 | J5: =IFERROR(SUM('Suivi des Chambres'!AO45:AQ84)/(COUNT('Suivi des Chambres'!$D$45:$D$84)*COLUMNS('Suivi des Chambres'!AO:AQ)),0) -> 0 | O5: =J5 -> 0 | Q5: R+3 | R5: =IFERROR(SUM('Suivi des Chambres'!AR45:AR84)/(COUNT('Suivi des Chambres'!$D$45:$D$84)*COLUMNS('Suivi des Chambres'!AR:AR)),0) -> 0.975 | W5: =R5 -> 0.975
A6: R+4 | B6: =IFERROR(SUM('Suivi des Chambres'!AN85:AN108)/(COUNT('Suivi des Chambres'!$D$85:$D$108)*COLUMNS('Suivi des Chambres'!AN:AN)),0) -> 0 | G6: =B6 -> 0 | I6: R+4 | J6: =IFERROR(SUM('Suivi des Chambres'!AO85:AQ108)/(COUNT('Suivi des Chambres'!$D$85:$D$108)*COLUMNS('Suivi des Chambres'!AO:AQ)),0) -> 0 | O6: =J6 -> 0 | Q6: R+4 | R6: =IFERROR(SUM('Suivi des Chambres'!AR85:AR108)/(COUNT('Suivi des Chambres'!$D$85:$D$108)*COLUMNS('Suivi des Chambres'!AR:AR)),0) -> 0 | W6: =R6 -> 0
A7: R+5 | B7: =IFERROR(SUM('Suivi des Chambres'!AN109:AN132)/(COUNT('Suivi des Chambres'!$D$109:$D$132)*COLUMNS('Suivi des Chambres'!AN:AN)),0) -> 0 | G7: =B7 -> 0 | I7: R+5 | J7: =IFERROR(SUM('Suivi des Chambres'!AO109:AQ132)/(COUNT('Suivi des Chambres'!$D$109:$D$132)*COLUMNS('Suivi des Chambres'!AO:AQ)),0) -> 0 | O7: =J7 -> 0 | Q7: R+5 | R7: =IFERROR(SUM('Suivi des Chambres'!AR109:AR132)/(COUNT('Suivi des Chambres'!$D$109:$D$132)*COLUMNS('Suivi des Chambres'!AR:AR)),0) -> 0 | W7: =R7 -> 0
A9: FAUX PLAFOND CHAMBRE | I9: MENUISERIE BOIS | Q9: MENUISERIE ALU
A10: R+2 | B10: =IFERROR(SUM('Suivi des Chambres'!AS5:AZ44)/(COUNT('Suivi des Chambres'!$D$5:$D$44)*COLUMNS('Suivi des Chambres'!AS:AZ)),0) -> 0.35203125 | G10: =B10 -> 0.35203125 | I10: R+2 | J10: =IFERROR(SUM('Suivi des Chambres'!BA5:BC44)/(COUNT('Suivi des Chambres'!$D$5:$D$44)*COLUMNS('Suivi des Chambres'!BA:BC)),0) -> 0.066666667 | O10: =J10 -> 0.066666667 | Q10: R+2 | R10: =IFERROR(SUM('Suivi des Chambres'!BD5:BD44)/(COUNT('Suivi des Chambres'!$D$5:$D$44)*COLUMNS('Suivi des Chambres'!BD:BD)),0) -> 0.125 | W10: =R10 -> 0.125
A11: R+3 | B11: =IFERROR(SUM('Suivi des Chambres'!AS45:AZ84)/(COUNT('Suivi des Chambres'!$D$45:$D$84)*COLUMNS('Suivi des Chambres'!AS:AZ)),0) -> 0.25 | G11: =B11 -> 0.25 | I11: R+3 | J11: =IFERROR(SUM('Suivi des Chambres'!BA45:BC84)/(COUNT('Suivi des Chambres'!$D$45:$D$84)*COLUMNS('Suivi des Chambres'!BA:BC)),0) -> 0 | O11: =J11 -> 0 | Q11: R+3 | R11: =IFERROR(SUM('Suivi des Chambres'!BD45:BD84)/(COUNT('Suivi des Chambres'!$D$45:$D$84)*COLUMNS('Suivi des Chambres'!BD:BD)),0) -> 0 | W11: =R11 -> 0
A12: R+4 | B12: =IFERROR(SUM('Suivi des Chambres'!AS85:AZ108)/(COUNT('Suivi des Chambres'!$D$85:$D$108)*COLUMNS('Suivi des Chambres'!AS:AZ)),0) -> 0 | G12: =B12 -> 0 | I12: R+4 | J12: =IFERROR(SUM('Suivi des Chambres'!BA85:BC108)/(COUNT('Suivi des Chambres'!$D$85:$D$108)*COLUMNS('Suivi des Chambres'!BA:BC)),0) -> 0 | O12: =J12 -> 0 | Q12: R+4 | R12: =IFERROR(SUM('Suivi des Chambres'!BD85:BD108)/(COUNT('Suivi des Chambres'!$D$85:$D$108)*COLUMNS('Suivi des Chambres'!BD:BD)),0) -> 0 | W12: =R12 -> 0
A13: R+5 | B13: =IFERROR(SUM('Suivi des Chambres'!AS109:AZ132)/(COUNT('Suivi des Chambres'!$D$109:$D$132)*COLUMNS('Suivi des Chambres'!AS:AZ)),0) -> 0 | G13: =B13 -> 0 | I13: R+5 | J13: =IFERROR(SUM('Suivi des Chambres'!BA109:BC132)/(COUNT('Suivi des Chambres'!$D$109:$D$132)*COLUMNS('Suivi des Chambres'!BA:BC)),0) -> 0 | O13: =J13 -> 0 | Q13: R+5 | R13: =IFERROR(SUM('Suivi des Chambres'!BD109:BD132)/(COUNT('Suivi des Chambres'!$D$109:$D$132)*COLUMNS('Suivi des Chambres'!BD:BD)),0) -> 0 | W13: =R13 -> 0
A15: PEINTURE | I15: REVÊTEMENT SOL | Q15: AGENCEMENT FIXE
A16: R+2 | B16: =IFERROR(SUM('Suivi des Chambres'!BE5:BH44)/(COUNT('Suivi des Chambres'!$D$5:$D$44)*COLUMNS('Suivi des Chambres'!BE:BH)),0) -> 0.0375 | G16: =B16 -> 0.0375 | I16: R+2 | J16: =IFERROR(SUM('Suivi des Chambres'!BI5:BJ44)/(COUNT('Suivi des Chambres'!$D$5:$D$44)*COLUMNS('Suivi des Chambres'!BI:BJ)),0) -> 0.05 | O16: =J16 -> 0.05 | Q16: R+2 | R16: =IFERROR(SUM('Suivi des Chambres'!BK5:BM44)/(COUNT('Suivi des Chambres'!$D$5:$D$44)*COLUMNS('Suivi des Chambres'!BK:BM)),0) -> 0 | W16: =R16 -> 0
A17: R+3 | B17: =IFERROR(SUM('Suivi des Chambres'!BE45:BH84)/(COUNT('Suivi des Chambres'!$D$45:$D$84)*COLUMNS('Suivi des Chambres'!BE:BH)),0) -> 0 | G17: =B17 -> 0 | I17: R+3 | J17: =IFERROR(SUM('Suivi des Chambres'!BI45:BJ84)/(COUNT('Suivi des Chambres'!$D$45:$D$84)*COLUMNS('Suivi des Chambres'!BI:BJ)),0) -> 0 | O17: =J17 -> 0 | Q17: R+3 | R17: =IFERROR(SUM('Suivi des Chambres'!BK45:BM84)/(COUNT('Suivi des Chambres'!$D$45:$D$84)*COLUMNS('Suivi des Chambres'!BK:BM)),0) -> 0 | W17: =R17 -> 0
A18: R+4 | B18: =IFERROR(SUM('Suivi des Chambres'!BE85:BH108)/(COUNT('Suivi des Chambres'!$D$85:$D$108)*COLUMNS('Suivi des Chambres'!BE:BH)),0) -> 0 | G18: =B18 -> 0 | I18: R+4 | J18: =IFERROR(SUM('Suivi des Chambres'!BI85:BJ108)/(COUNT('Suivi des Chambres'!$D$85:$D$108)*COLUMNS('Suivi des Chambres'!BI:BJ)),0) -> 0 | O18: =J18 -> 0 | Q18: R+4 | R18: =IFERROR(SUM('Suivi des Chambres'!BK85:BM108)/(COUNT('Suivi des Chambres'!$D$85:$D$108)*COLUMNS('Suivi des Chambres'!BK:BM)),0) -> 0 | W18: =R18 -> 0
A19: R+5 | B19: =IFERROR(SUM('Suivi des Chambres'!BE109:BH132)/(COUNT('Suivi des Chambres'!$D$109:$D$132)*COLUMNS('Suivi des Chambres'!BE:BH)),0) -> 0 | G19: =B19 -> 0 | I19: R+5 | J19: =IFERROR(SUM('Suivi des Chambres'!BI109:BJ132)/(COUNT('Suivi des Chambres'!$D$109:$D$132)*COLUMNS('Suivi des Chambres'!BI:BJ)),0) -> 0 | O19: =J19 -> 0 | Q19: R+5 | R19: =IFERROR(SUM('Suivi des Chambres'!BK109:BM132)/(COUNT('Suivi des Chambres'!$D$109:$D$132)*COLUMNS('Suivi des Chambres'!BK:BM)),0) -> 0 | W19: =R19 -> 0
A21: APPAREILLAGE | I21: RÉCEPTION | Q21: LOGGIA
A22: R+2 | B22: =IFERROR(SUM('Suivi des Chambres'!BN5:BO44)/(COUNT('Suivi des Chambres'!$D$5:$D$44)*COLUMNS('Suivi des Chambres'!BN:BO)),0) -> 0 | G22: =B22 -> 0 | I22: R+2 | J22: =IFERROR(SUM('Suivi des Chambres'!#REF!)/(COUNT('Suivi des Chambres'!$D$5:$D$44)*COLUMNS('Suivi des Chambres'!#REF!)),0) -> 0 | O22: =J22 -> 0 | Q22: R+2 | R22: =IFERROR(SUM('Suivi des Chambres'!BS5:BT44)/(COUNT('Suivi des Chambres'!$D$5:$D$44)*COLUMNS('Suivi des Chambres'!BS:BT)),0) -> 0 | W22: =R22 -> 0
A23: R+3 | B23: =IFERROR(SUM('Suivi des Chambres'!BN45:BO84)/(COUNT('Suivi des Chambres'!$D$45:$D$84)*COLUMNS('Suivi des Chambres'!BN:BO)),0) -> 0 | G23: =B23 -> 0 | I23: R+3 | J23: =IFERROR(SUM('Suivi des Chambres'!#REF!)/(COUNT('Suivi des Chambres'!$D$45:$D$84)*COLUMNS('Suivi des Chambres'!#REF!)),0) -> 0 | O23: =J23 -> 0 | Q23: R+3 | R23: =IFERROR(SUM('Suivi des Chambres'!BS45:BT84)/(COUNT('Suivi des Chambres'!$D$45:$D$84)*COLUMNS('Suivi des Chambres'!BS:BT)),0) -> 0 | W23: =R23 -> 0
A24: R+4 | B24: =IFERROR(SUM('Suivi des Chambres'!BN85:BO108)/(COUNT('Suivi des Chambres'!$D$85:$D$108)*COLUMNS('Suivi des Chambres'!BN:BO)),0) -> 0 | G24: =B24 -> 0 | I24: R+4 | J24: =IFERROR(SUM('Suivi des Chambres'!#REF!)/(COUNT('Suivi des Chambres'!$D$85:$D$108)*COLUMNS('Suivi des Chambres'!#REF!)),0) -> 0 | O24: =J24 -> 0 | Q24: R+4 | R24: =IFERROR(SUM('Suivi des Chambres'!BS85:BT108)/(COUNT('Suivi des Chambres'!$D$85:$D$108)*COLUMNS('Suivi des Chambres'!BS:BT)),0) -> 0 | W24: =R24 -> 0
A25: R+5 | B25: =IFERROR(SUM('Suivi des Chambres'!BN109:BO132)/(COUNT('Suivi des Chambres'!$D$109:$D$132)*COLUMNS('Suivi des Chambres'!BN:BO)),0) -> 0 | G25: =B25 -> 0 | I25: R+5 | J25: =IFERROR(SUM('Suivi des Chambres'!#REF!)/(COUNT('Suivi des Chambres'!$D$109:$D$132)*COLUMNS('Suivi des Chambres'!#REF!)),0) -> 0 | O25: =J25 -> 0 | Q25: R+5 | R25: =IFERROR(SUM('Suivi des Chambres'!BS109:BT132)/(COUNT('Suivi des Chambres'!$D$109:$D$132)*COLUMNS('Suivi des Chambres'!BS:BT)),0) -> 0 | W25: =R25 -> 0
